Traceback (most recent call last):
  File "/home/jip/anaconda3/lib/python3.10/site-packages/jupyter_cache/executors/utils.py", line 58, in single_nb_execution
    executenb(
  File "/home/jip/anaconda3/lib/python3.10/site-packages/nbclient/client.py", line 1204, in execute
    return NotebookClient(nb=nb, resources=resources, km=km, **kwargs).execute()
  File "/home/jip/anaconda3/lib/python3.10/site-packages/nbclient/util.py", line 84, in wrapped
    return just_run(coro(*args, **kwargs))
  File "/home/jip/anaconda3/lib/python3.10/site-packages/nbclient/util.py", line 62, in just_run
    return loop.run_until_complete(coro)
  File "/home/jip/anaconda3/lib/python3.10/asyncio/base_events.py", line 649, in run_until_complete
    return future.result()
  File "/home/jip/anaconda3/lib/python3.10/site-packages/nbclient/client.py", line 663, in async_execute
    await self.async_execute_cell(
  File "/home/jip/anaconda3/lib/python3.10/site-packages/nbclient/client.py", line 965, in async_execute_cell
    await self._check_raise_for_error(cell, cell_index, exec_reply)
  File "/home/jip/anaconda3/lib/python3.10/site-packages/nbclient/client.py", line 862, in _check_raise_for_error
    raise CellExecutionError.from_cell_and_msg(cell, exec_reply_content)
nbclient.exceptions.CellExecutionError: An error occurred while executing the following cell:
------------------
from PIL import Image
import matplotlib.pyplot as plt

# Voer het pad naar je afbeelding in
image_path = '../images/tennisveld.jpg'

# Open de afbeelding met Pillow
image = Image.open(image_path)

# Gebruik matplotlib om de afbeelding te tonen
plt.imshow(image)
plt.axis('off')  # Verberg de assen
plt.show()


------------------

[0;31m---------------------------------------------------------------------------[0m
[0;31mFileNotFoundError[0m                         Traceback (most recent call last)
Cell [0;32mIn[1], line 8[0m
[1;32m      5[0m image_path [38;5;241m=[39m [38;5;124m'[39m[38;5;124m../images/tennisveld.jpg[39m[38;5;124m'[39m
[1;32m      7[0m [38;5;66;03m# Open de afbeelding met Pillow[39;00m
[0;32m----> 8[0m image [38;5;241m=[39m [43mImage[49m[38;5;241;43m.[39;49m[43mopen[49m[43m([49m[43mimage_path[49m[43m)[49m
[1;32m     10[0m [38;5;66;03m# Gebruik matplotlib om de afbeelding te tonen[39;00m
[1;32m     11[0m plt[38;5;241m.[39mimshow(image)

File [0;32m~/anaconda3/lib/python3.10/site-packages/PIL/Image.py:3227[0m, in [0;36mopen[0;34m(fp, mode, formats)[0m
[1;32m   3224[0m     filename [38;5;241m=[39m fp
[1;32m   3226[0m [38;5;28;01mif[39;00m filename:
[0;32m-> 3227[0m     fp [38;5;241m=[39m [43mbuiltins[49m[38;5;241;43m.[39;49m[43mopen[49m[43m([49m[43mfilename[49m[43m,[49m[43m [49m[38;5;124;43m"[39;49m[38;5;124;43mrb[39;49m[38;5;124;43m"[39;49m[43m)[49m
[1;32m   3228[0m     exclusive_fp [38;5;241m=[39m [38;5;28;01mTrue[39;00m
[1;32m   3230[0m [38;5;28;01mtry[39;00m:

[0;31mFileNotFoundError[0m: [Errno 2] No such file or directory: '../images/tennisveld.jpg'
FileNotFoundError: [Errno 2] No such file or directory: '../images/tennisveld.jpg'

